<?xml version="1.0" ?>

<!-- 

author danu andrean 
date  9 mei 2021
approach darwin op3 inertia 

-->

<robot name="rscuad" xmlns:xacro="http://www.ros.org/wiki/xacro">

  <xacro:property name="PI" value="3.1415926535897931"/>
  <xacro:include filename="$(find rscuad_description)/urdf/rscuad.gazebo" />
  <xacro:include filename="$(find rscuad_description)/urdf/transmission.xacro" />
  
 
  <link
    name="body">
    <inertial>
      <origin
        xyz="0.0357056190627579 0.0719364874349917 0.124774491029847"
        rpy="0 0 0" />
      <mass
        value="0.845681147773924" />
      <inertia ixx="0.00340499" ixy="0.00000572" ixz="-0.00004256"
             iyy="0.00296939" iyz="-0.00000059"
             izz="0.00317331" />
    </inertial>
    <visual>
      <origin
        xyz="0 0 0"
        rpy="0 0 0" />
      <geometry>
        <mesh
          filename="package://rscuad_description/meshes/body.STL" />
      </geometry>
      <material
        name="">
        <color
          rgba="0.752941176470588 0.752941176470588 0.752941176470588 1" />
      </material>
    </visual>
    <collision>
      <origin
        xyz="0 0 0"
        rpy="0 0 0" />
      <geometry>
        <mesh
          filename="package://rscuad_description/meshes/body.STL" />
      </geometry>
    </collision>
  </link>
  <link
    name="head_pan">
    <inertial>
      <origin
        xyz="5.68989300120393E-16 -0.00822795113008323 0.0023274800004647"
        rpy="0 0 0" />
      <mass
        value="0.0127468700670499" />
      <inertia ixx="0.00000397" ixy="0.0" ixz="-0.00000031"
             iyy="0.00000165" iyz="0.0"
             izz="0.00000387" />
    </inertial>
    <visual>
      <origin
        xyz="0 0 0"
        rpy="0 0 0" />
      <geometry>
        <mesh
          filename="package://rscuad_description/meshes/head_pan.STL" />
      </geometry>
      <material
        name="">
        <color
          rgba="0.898039215686275 0.917647058823529 0.929411764705882 1" />
      </material>
    </visual>
    <collision>
      <origin
        xyz="0 0 0"
        rpy="0 0 0" />
      <geometry>
        <mesh
          filename="package://rscuad_description/meshes/head_pan.STL" />
      </geometry>
    </collision>
  </link>
  <joint
    name="head_pan"
    type="revolute">
    <origin
      xyz="0.035958 -0.1394 0.14298"
      rpy="-1.5708 0 -3.1416" />
    <parent
      link="body" />
    <child
      link="head_pan" />
    <axis
      xyz="0 1 0" />
     <limit effort="1000" velocity="10" lower="${-pi*0.9}" upper="${pi*0.9}" />
  </joint>
  <insert_transmission name="head_pan"/>

  <link
    name="head_tilt">
    <inertial>
      <origin
        xyz="0.000104621828214489 0.0371739829464326 0.000780731992570616"
        rpy="0 0 0" />
      <mass
        value="0.12573924511903" />
      <inertia ixx="0.00010612" ixy="0.00000011" ixz="-0.00000910"
             iyy="0.00008721" iyz="0.00000084"
             izz="0.00004529" />
    </inertial>
    <visual>
      <origin
        xyz="0 0 0"
        rpy="0 0 0" />
      <geometry>
        <mesh
          filename="package://rscuad_description/meshes/head_tilt.STL" />
      </geometry>
      <material
        name="">
        <color
          rgba="0.752941176470588 0.752941176470588 0.752941176470588 1" />
      </material>
    </visual>
    <collision>
      <origin
        xyz="0 0 0"
        rpy="0 0 0" />
      <geometry>
        <mesh
          filename="package://rscuad_description/meshes/head_tilt.STL" />
      </geometry>
    </collision>
  </link>
  <joint
    name="head_tilt"
    type="revolute">
    <origin
      xyz="0 -0.0285 0.01"
      rpy="0 0 3.1416" />
    <parent
      link="head_pan" />
    <child
      link="head_tilt" />
    <axis
      xyz="-1 0 0" />
     <limit effort="1000" velocity="10" lower="${-pi*0.9}" upper="${pi*0.9}" />
  </joint>

  <insert_transmission name="head_tilt"/>
<!-- ================================================ hand left -->

  <link
    name="l_sho_pitch">
    <inertial>
      <origin
        xyz="0.0152336162387284 -0.00180063582781188 6.66133814775094E-16"
        rpy="0 0 0" />
      <mass
        value="0.016476449424892" />
      <inertia ixx="0.00000165" ixy="0.0" ixz="0.0"
             iyy="0.00000387" iyz="0.00000031"
             izz="0.00000397" />
    </inertial>
    <visual>
      <origin
        xyz="0 0 0"
        rpy="0 0 0" />
      <geometry>
        <mesh
          filename="package://rscuad_description/meshes/l_sho_pitch.STL" />
      </geometry>
      <material
        name="">
        <color
          rgba="0.752941176470588 0.752941176470588 0.752941176470588 1" />
      </material>
    </visual>
    <collision>
      <origin
        xyz="0 0 0"
        rpy="0 0 0" />
      <geometry>
        <mesh
          filename="package://rscuad_description/meshes/l_sho_pitch.STL" />
      </geometry>
    </collision>
  </link>
  <joint
    name="l_sho_pitch"
    type="revolute">
    <origin
      xyz="0.10096 -0.1394 0.12423"
      rpy="1.5708 0 0" />
    <parent
      link="body" />
    <child
      link="l_sho_pitch" />
    <axis
      xyz="-1 0 0" />
     <limit effort="1000" velocity="10" lower="${-pi*0.9}" upper="${pi*0.9}" />
  </joint>
  <insert_transmission name="l_sho_pitch"/>

  <link
    name="l_sho_roll">
    <inertial>
      <origin
        xyz="0.0315938109781102 0.000680134592121545 0.000553421997326997"
        rpy="0 0 0" />
      <mass
        value="0.0884003305596694" />
      <inertia ixx="0.00022804" ixy="-0.00000001" ixz="0.00000003"
             iyy="0.00003042" iyz="0.00000059"
             izz="0.00023474" />
    </inertial>
    <visual>
      <origin
        xyz="0 0 0"
        rpy="0 0 0" />
      <geometry>
        <mesh
          filename="package://rscuad_description/meshes/l_sho_roll.STL" />
      </geometry>
      <material
        name="">
        <color
          rgba="0.752941176470588 0.752941176470588 0.752941176470588 1" />
      </material>
    </visual>
    <collision>
      <origin
        xyz="0 0 0"
        rpy="0 0 0" />
      <geometry>
        <mesh
          filename="package://rscuad_description/meshes/l_sho_roll.STL" />
      </geometry>
    </collision>
  </link>
  <joint
    name="l_sho_roll"
    type="revolute">
    <origin
      xyz="0.0385 -0.01 0"
      rpy="0 0 0" />
    <parent
      link="l_sho_pitch" />
    <child
      link="l_sho_roll" />
    <axis
      xyz="0 0 -1" />
    <limit effort="1000" velocity="10" lower="${-pi*0.9}" upper="${pi*0.9}" />
  </joint>
  <insert_transmission name="l_sho_roll"/>

  <link
    name="l_el">
    <inertial>
      <origin
        xyz="0.0134578975462598 0.00385263451594457 0.0152675229649245"
        rpy="0 0 0" />
      <mass
        value="0.0561826372694756" />
      <inertia ixx="0.00006196" ixy="0.0" ixz="0.0"
             iyy="0.00001231" iyz="-0.00000372"
             izz="0.00006854" />
    </inertial>
    <visual>
      <origin
        xyz="0 0 0"
        rpy="0 0 0" />
      <geometry>
        <mesh
          filename="package://rscuad_description/meshes/l_el.STL" />
      </geometry>
      <material
        name="">
        <color
          rgba="0.752941176470588 0.752941176470588 0.752941176470588 1" />
      </material>
    </visual>
    <collision>
      <origin
        xyz="0 0 0"
        rpy="0 0 0" />
      <geometry>
        <mesh
          filename="package://rscuad_description/meshes/l_el.STL" />
      </geometry>
    </collision>
  </link>
  <joint
    name="l_el"
    type="revolute">
    <origin
      xyz="0.0874466726391421 0 0.0100000000000002"
      rpy="0 0 0" />
    <parent
      link="l_sho_roll" />
    <child
      link="l_el" />
    <axis
      xyz="0 -1 0" />
     <limit effort="1000" velocity="10" lower="${-pi*0.9}" upper="${pi*0.9}" />
  </joint>
  <insert_transmission name="l_el"/>


<!-- ================================================ hand right -->
  <link
    name="r_sho_pitch">
    <inertial>
      <origin
        xyz="-0.0152336162387284 -0.00180063582780762 -2.77555756156289E-15"
        rpy="0 0 0" />
      <mass
        value="0.0164764494248921" />
      <inertia ixx="0.00000165" ixy="0.0" ixz="0.0"
             iyy="0.00000387" iyz="-0.00000031"
             izz="0.00000397" />
    </inertial>
    <visual>
      <origin
        xyz="0 0 0"
        rpy="0 0 0" />
      <geometry>
        <mesh
          filename="package://rscuad_description/meshes/r_sho_pitch.STL" />
      </geometry>
      <material
        name="">
        <color
          rgba="0.752941176470588 0.752941176470588 0.752941176470588 1" />
      </material>
    </visual>
    <collision>
      <origin
        xyz="0 0 0"
        rpy="0 0 0" />
      <geometry>
        <mesh
          filename="package://rscuad_description/meshes/r_sho_pitch.STL" />
      </geometry>
    </collision>
  </link>
  <joint
    name="r_sho_pitch"
    type="revolute">
    <origin
      xyz="-0.0290205030447131 -0.139400454049433 0.124229542783902"
      rpy="1.5707963267949 0 0" />
    <parent
      link="body" />
    <child
      link="r_sho_pitch" />
    <axis
      xyz="-1 0 0" />
     <limit effort="1000" velocity="10" lower="${-pi*0.9}" upper="${pi*0.9}" />
  </joint>
  <insert_transmission name="r_sho_pitch"/>

  <link
    name="r_sho_roll">
    <inertial>
      <origin
        xyz="-0.0346452133269944 0.000680134426259818 0.000553937880485106"
        rpy="0 0 0" />
      <mass
        value="0.0884003307974895" />
      <inertia ixx="0.00022804" ixy="0.00000001" ixz="0.00000003"
             iyy="0.00003042" iyz="-0.00000059"
             izz="0.00023474" />
    </inertial>
    <visual>
      <origin
        xyz="0 0 0"
        rpy="0 0 0" />
      <geometry>
        <mesh
          filename="package://rscuad_description/meshes/r_sho_roll.STL" />
      </geometry>
      <material
        name="">
        <color
          rgba="0.752941176470588 0.752941176470588 0.752941176470588 1" />
      </material>
    </visual>
    <collision>
      <origin
        xyz="0 0 0"
        rpy="0 0 0" />
      <geometry>
        <mesh
          filename="package://rscuad_description/meshes/r_sho_roll.STL" />
      </geometry>
    </collision>
  </link>
  <joint
    name="r_sho_roll"
    type="revolute">
    <origin
      xyz="-0.0384999999999999 -0.00999999999999629 0"
      rpy="0 0 0" />
    <parent
      link="r_sho_pitch" />
    <child
      link="r_sho_roll" />
    <axis
      xyz="0 0 -1" />
     <limit effort="1000" velocity="10" lower="${-pi*0.9}" upper="${pi*0.9}" />
  </joint>
  <insert_transmission name="r_sho_roll"/>

  <link
    name="r_el">
    <inertial>
      <origin
        xyz="-0.0134578975462585 0.00385263451578942 0.0152675231335785"
        rpy="0 0 0" />
      <mass
        value="0.0561826372694755" />
      <inertia ixx="0.00006196" ixy="0.0" ixz="0.0"
             iyy="0.00001231" iyz="0.00000372"
             izz="0.00006854" />
    </inertial>
    <visual>
      <origin
        xyz="0 0 0"
        rpy="0 0 0" />
      <geometry>
        <mesh
          filename="package://rscuad_description/meshes/r_el.STL" />
      </geometry>
      <material
        name="">
        <color
          rgba="0.752941176470588 0.752941176470588 0.752941176470588 1" />
      </material>
    </visual>
    <collision>
      <origin
        xyz="0 0 0"
        rpy="0 0 0" />
      <geometry>
        <mesh
          filename="package://rscuad_description/meshes/r_el.STL" />
      </geometry>
    </collision>
  </link>
  <joint
    name="r_el"
    type="revolute">
    <origin
      xyz="-0.0936500000000009 0 0.0099999999999961"
      rpy="0 0 0" />
    <parent
      link="r_sho_roll" />
    <child
      link="r_el" />
    <axis
      xyz="0 -1 0" />
     <limit effort="1000" velocity="10" lower="${-pi*0.9}" upper="${pi*0.9}" />
  </joint>
  <insert_transmission name="r_el"/>


<!-- =====================================================leg left -->

  <link
    name="l_hip_yaw">
    <inertial>
      <origin
        xyz="-4.29815663380295E-07 -0.0108141173114426 0.00278343252511654"
        rpy="0 0 0" />
      <mass
        value="0.0229829364852389" />
      <inertia ixx="0.00000151" ixy="0.0" ixz="0.00000001"
             iyy="0.00000430" iyz="0.0"
             izz="0.00000412" />
    </inertial>
    <visual>
      <origin
        xyz="0 0 0"
        rpy="0 0 0" />
      <geometry>
        <mesh
          filename="package://rscuad_description/meshes/l_hip_yaw.STL" />
      </geometry>
      <material
        name="">
        <color
          rgba="0.752941176470588 0.752941176470588 0.752941176470588 1" />
      </material>
    </visual>
    <collision>
      <origin
        xyz="0 0 0"
        rpy="0 0 0" />
      <geometry>
        <mesh
          filename="package://rscuad_description/meshes/l_hip_yaw.STL" />
      </geometry>
    </collision>
  </link>
  <joint
    name="l_hip_yaw"
    type="revolute">
    <origin
      xyz="0.0809483118859766 -0.13794445404943 0.00675246433967373"
      rpy="1.5707963267949 0.00102499964103206 0" />
    <parent
      link="body" />
    <child
      link="l_hip_yaw" />
    <axis
      xyz="0 -1 0" />
     <limit effort="1000" velocity="10" lower="${-pi*0.9}" upper="${pi*0.9}" />
  </joint>
  <insert_transmission name="l_hip_yaw"/>

  <link
    name="l_hip_roll">
    <inertial>
      <origin
        xyz="-0.000117953958974196 -0.0149128586946627 -0.0249453119100794"
        rpy="0 0 0" />
      <mass
        value="0.151586182496668" />
      <inertia ixx="0.00004661" ixy="-0.00000101" ixz="-0.00000131"
             iyy="0.00012523" iyz="-0.00000006"
             izz="0.00010857" />
    </inertial>
    <visual>
      <origin
        xyz="0 0 0"
        rpy="0 0 0" />
      <geometry>
        <mesh
          filename="package://rscuad_description/meshes/l_hip_roll.STL" />
      </geometry>
      <material
        name="">
        <color
          rgba="0.752941176470588 0.752941176470588 0.752941176470588 1" />
      </material>
    </visual>
    <collision>
      <origin
        xyz="0 0 0"
        rpy="0 0 0" />
      <geometry>
        <mesh
          filename="package://rscuad_description/meshes/l_hip_roll.STL" />
      </geometry>
    </collision>
  </link>
  <joint
    name="l_hip_roll"
    type="revolute">
    <origin
      xyz="0 -0.0360348499633859 0"
      rpy="0 0 0.00102499964103206" />
    <parent
      link="l_hip_yaw" />
    <child
      link="l_hip_roll" />
    <axis
      xyz="0 0 -1" />
     <limit effort="1000" velocity="10" lower="${-pi*0.9}" upper="${pi*0.9}" />
  </joint>
  <insert_transmission name="l_hip_roll"/>

  <link
    name="l_hip_pitch">
    <inertial>
      <origin
        xyz="0.000243254808011836 -0.0898667305909595 0.000209659949259006"
        rpy="0 0 0" />
      <mass
        value="0.100631639038866" />
      <inertia ixx="0.00010499" ixy="-0.00000001" ixz="-0.00000071"
             iyy="0.00009613" iyz="0.00000353"
             izz="0.00002493" />
    </inertial>
    <visual>
      <origin
        xyz="0 0 0"
        rpy="0 0 0" />
      <geometry>
        <mesh
          filename="package://rscuad_description/meshes/l_hip_pitch.STL" />
      </geometry>
      <material
        name="">
        <color
          rgba="0.752941176470588 0.752941176470588 0.752941176470588 1" />
      </material>
    </visual>
    <collision>
      <origin
        xyz="0 0 0"
        rpy="0 0 0" />
      <geometry>
        <mesh
          filename="package://rscuad_description/meshes/l_hip_pitch.STL" />
      </geometry>
    </collision>
  </link>
  <joint
    name="l_hip_pitch"
    type="revolute">
    <origin
      xyz="0 0 -0.000599999999901152"
      rpy="-0.3 0 0" />
    <parent
      link="l_hip_roll" />
    <child
      link="l_hip_pitch" />
    <axis
      xyz="-1 0 0" />
     <limit effort="1000" velocity="10" lower="${-pi*0.9}" upper="${pi*0.9}" />
  </joint>
  <insert_transmission name="l_hip_pitch"/>

  <link
    name="l_knee">
    <inertial>
      <origin
        xyz="-0.000851388457390925 -0.0468684890675609 0.00801828716169498"
        rpy="0 0 0" />
      <mass
        value="0.0624359207391482" />
      <inertia ixx="0.00003715" ixy="0.0" ixz="0.0"
             iyy="0.00002751" iyz="0.0"
             izz="0.00001511" />
    </inertial>
    <visual>
      <origin
        xyz="0 0 0"
        rpy="0 0 0" />
      <geometry>
        <mesh
          filename="package://rscuad_description/meshes/l_knee.STL" />
      </geometry>
      <material
        name="">
        <color
          rgba="0.752941176470588 0.752941176470588 0.752941176470588 1" />
      </material>
    </visual>
    <collision>
      <origin
        xyz="0 0 0"
        rpy="0 0 0" />
      <geometry>
        <mesh
          filename="package://rscuad_description/meshes/l_knee.STL" />
      </geometry>
    </collision>
  </link>
  <joint
    name="l_knee"
    type="revolute">
    <origin
      xyz="0 -0.121999999999998 -3.60787874466861E-05"
      rpy="0.5 0 0" />
    <parent
      link="l_hip_pitch" />
    <child
      link="l_knee" />
    <axis
      xyz="-1 0 0" />
     <limit effort="1000" velocity="10" lower="${-pi*0.9}" upper="${pi*0.9}" />
  </joint>
  <insert_transmission name="l_knee"/>

  <link
    name="l_ank_pitch">
    <inertial>
      <origin
        xyz="0.000117962348445882 -0.0149128586946611 -0.0243453045375506"
        rpy="0 0 0" />
      <mass
        value="0.151586182496668" />
      <inertia ixx="0.00004661" ixy="-0.00000101" ixz="0.00000131"
             iyy="0.00012523" iyz="0.00000006"
             izz="0.00010857" />
    </inertial>
    <visual>
      <origin
        xyz="0 0 0"
        rpy="0 0 0" />
      <geometry>
        <mesh
          filename="package://rscuad_description/meshes/l_ank_pitch.STL" />
      </geometry>
      <material
        name="">
        <color
          rgba="0.752941176470588 0.752941176470588 0.752941176470588 1" />
      </material>
    </visual>
    <collision>
      <origin
        xyz="0 0 0"
        rpy="0 0 0" />
      <geometry>
        <mesh
          filename="package://rscuad_description/meshes/l_ank_pitch.STL" />
      </geometry>
    </collision>
  </link>
  <joint
    name="l_ank_pitch"
    type="revolute">
    <origin
      xyz="0 -0.12200007459305 0.000539974593052855"
      rpy="0.5 0 -3.14159265358979" />
    <parent
      link="l_knee" />
    <child
      link="l_ank_pitch" />
    <axis
      xyz="1 0 0" />
     <limit effort="1000" velocity="10" lower="${-pi*0.9}" upper="${pi*0.9}" />
  </joint>
  <insert_transmission name="l_ank_pitch"/>

  <link
    name="l_ank_roll">
    <inertial>
      <origin
        xyz="0.00433834985207866 -0.0308901133838574 0.0023510035149302"
        rpy="0 0 0" />
      <mass
        value="0.0443088669743472" />
      <inertia ixx="0.00004034" ixy="-0.00000019" ixz="0.00000012"
             iyy="0.00007874" iyz="0.00000101"
             izz="0.00011579" />
    </inertial>
    <visual>
      <origin
        xyz="0 0 0"
        rpy="0 0 0" />
      <geometry>
        <mesh
          filename="package://rscuad_description/meshes/l_ank_roll.STL" />
      </geometry>
      <material
        name="">
        <color
          rgba="0.752941176470588 0.752941176470588 0.752941176470588 1" />
      </material>
    </visual>
    <collision>
      <origin
        xyz="0 0 0"
        rpy="0 0 0" />
      <geometry>
        <mesh
          filename="package://rscuad_description/meshes/l_ank_roll.STL" />
      </geometry>
    </collision>
  </link>
  <joint
    name="l_ank_roll"
    type="revolute">
    <origin
      xyz="0 0 0"
      rpy="0 0 3.14159265358979" />
    <parent
      link="l_ank_pitch" />
    <child
      link="l_ank_roll" />
    <axis
      xyz="0 0 -1" />
     <limit effort="1000" velocity="10" lower="${-pi*0.9}" upper="${pi*0.9}" />
  </joint>
  <insert_transmission name="l_ank_roll"/>
<!-- =====================================================leg right -->
  <link
    name="r_hip_yaw">
    <inertial>
      <origin
        xyz="-4.29815663359479E-07 -0.010814117311443 0.00278343252511634"
        rpy="0 0 0" />
      <mass
        value="0.0229829364852389" />
      <inertia ixx="0.00000151" ixy="0.0" ixz="0.00000001"
             iyy="0.00000430" iyz="0.0"
             izz="0.00000412" />
    </inertial>
    <visual>
      <origin
        xyz="0 0 0"
        rpy="0 0 0" />
      <geometry>
        <mesh
          filename="package://rscuad_description/meshes/r_hip_yaw.STL" />
      </geometry>
      <material
        name="">
        <color
          rgba="0.752941176470588 0.752941176470588 0.752941176470588 1" />
      </material>
    </visual>
    <collision>
      <origin
        xyz="0 0 0"
        rpy="0 0 0" />
      <geometry>
        <mesh
          filename="package://rscuad_description/meshes/r_hip_yaw.STL" />
      </geometry>
    </collision>
  </link>
  <joint
    name="r_hip_yaw"
    type="revolute">
    <origin
      xyz="-0.00903979651901684 -0.13794425404943 0.00679279956234802"
      rpy="1.5707963267949 0.00102499964103848 0" />
    <parent
      link="body" />
    <child
      link="r_hip_yaw" />
    <axis
      xyz="0 -1 0" />
     <limit effort="1000" velocity="10" lower="${-pi*0.9}" upper="${pi*0.9}" />
  </joint>
  <insert_transmission name="r_hip_yaw"/>

  <link
    name="r_hip_roll">
    <inertial>
      <origin
        xyz="0.000117962348444769 -0.0149128586946632 -0.0249453045374453"
        rpy="0 0 0" />
      <mass
        value="0.151586182496668" />
      <inertia ixx="0.00004661" ixy="0.00000101" ixz="-0.00000131"
             iyy="0.00012523" iyz="0.00000006"
             izz="0.00010857" />
    </inertial>
    <visual>
      <origin
        xyz="0 0 0"
        rpy="0 0 0" />
      <geometry>
        <mesh
          filename="package://rscuad_description/meshes/r_hip_roll.STL" />
      </geometry>
      <material
        name="">
        <color
          rgba="0.752941176470588 0.752941176470588 0.752941176470588 1" />
      </material>
    </visual>
    <collision>
      <origin
        xyz="0 0 0"
        rpy="0 0 0" />
      <geometry>
        <mesh
          filename="package://rscuad_description/meshes/r_hip_roll.STL" />
      </geometry>
    </collision>
  </link>
  <joint
    name="r_hip_roll"
    type="revolute">
    <origin
      xyz="0 -0.0360348499633864 0"
      rpy="0 0 0.00102499964103848" />
    <parent
      link="r_hip_yaw" />
    <child
      link="r_hip_roll" />
    <axis
      xyz="0 0 -1" />
     <limit effort="1000" velocity="10" lower="${-pi*0.9}" upper="${pi*0.9}" />
  </joint>
  <insert_transmission name="r_hip_roll"/>

  <link
    name="r_hip_pitch">
    <inertial>
      <origin
        xyz="-0.00023617866960057 -0.0898667305909591 0.0002096488435121"
        rpy="0 0 0" />
      <mass
        value="0.100631639038866" />
      <inertia ixx="0.00010499" ixy="0.00000001" ixz="-0.00000071"
             iyy="0.00009613" iyz="-0.00000353"
             izz="0.00002493" />
    </inertial>
    <visual>
      <origin
        xyz="0 0 0"
        rpy="0 0 0" />
      <geometry>
        <mesh
          filename="package://rscuad_description/meshes/r_hip_pitch.STL" />
      </geometry>
      <material
        name="">
        <color
          rgba="0.752941176470588 0.752941176470588 0.752941176470588 1" />
      </material>
    </visual>
    <collision>
      <origin
        xyz="0 0 0"
        rpy="0 0 0" />
      <geometry>
        <mesh
          filename="package://rscuad_description/meshes/r_hip_pitch.STL" />
      </geometry>
    </collision>
  </link>
  <joint
    name="r_hip_pitch"
    type="revolute">
    <origin
      xyz="0 0 -0.000599999999901429"
      rpy="-0.3 0 0" />
    <parent
      link="r_hip_roll" />
    <child
      link="r_hip_pitch" />
    <axis
      xyz="-1 0 0" />
     <limit effort="1000" velocity="10" lower="${-pi*0.9}" upper="${pi*0.9}" />
  </joint>
  <insert_transmission name="r_hip_pitch"/>

  <link
    name="r_knee">
    <inertial>
      <origin
        xyz="0.000851143901047947 -0.0468684890675623 0.00801828716169503"
        rpy="0 0 0" />
      <mass
        value="0.0624359207391501" />
      <inertia ixx="0.00003715" ixy="0.0" ixz="0.0"
             iyy="0.00002751" iyz="0.0"
             izz="0.00001511" />
    </inertial>
    <visual>
      <origin
        xyz="0 0 0"
        rpy="0 0 0" />
      <geometry>
        <mesh
          filename="package://rscuad_description/meshes/r_knee.STL" />
      </geometry>
      <material
        name="">
        <color
          rgba="0.752941176470588 0.752941176470588 0.752941176470588 1" />
      </material>
    </visual>
    <collision>
      <origin
        xyz="0 0 0"
        rpy="0 0 0" />
      <geometry>
        <mesh
          filename="package://rscuad_description/meshes/r_knee.STL" />
      </geometry>
    </collision>
  </link>
  <joint
    name="r_knee"
    type="revolute">
    <origin
      xyz="0 -0.121999999999998 -3.60787874468527E-05"
      rpy="0.5 0 0" />
    <parent
      link="r_hip_pitch" />
    <child
      link="r_knee" />
    <axis
      xyz="1 0 0" />
    <!-- <limit effort="1000" velocity="100" lower="${-pi*0.9}" upper="${pi*0.9}" /> -->
     <limit effort="1000" velocity="10" lower="${-pi*0.9}" upper="${pi*0.9}" />
  </joint>
  <insert_transmission name="r_knee"/>

  <link
    name="r_ank_pitch">
    <inertial>
      <origin
        xyz="-0.000117953958976062 -0.0149128586946587 -0.0243453119101897"
        rpy="0 0 0" />
      <mass
        value="0.151586182496669" />
      <inertia ixx="0.00004661" ixy="0.00000101" ixz="0.00000131"
             iyy="0.00012523" iyz="-0.00000006"
             izz="0.00010857" />
    </inertial>
    <visual>
      <origin
        xyz="0 0 0"
        rpy="0 0 0" />
      <geometry>
        <mesh
          filename="package://rscuad_description/meshes/r_ank_pitch.STL" />
      </geometry>
      <material
        name="">
        <color
          rgba="0.752941176470588 0.752941176470588 0.752941176470588 1" />
      </material>
    </visual>
    <collision>
      <origin
        xyz="0 0 0"
        rpy="0 0 0" />
      <geometry>
        <mesh
          filename="package://rscuad_description/meshes/r_ank_pitch.STL" />
      </geometry>
    </collision>
  </link>
  <joint
    name="r_ank_pitch"
    type="revolute">
    <origin
      xyz="0 -0.122 0.00053997"
      rpy="0.5 0 -3.1416" />
    <parent
      link="r_knee" />
    <child
      link="r_ank_pitch" />
    <axis
      xyz="1 0 0" />
     <limit effort="1000" velocity="10" lower="${-pi*0.9}" upper="${pi*0.9}" />
  </joint>
  <insert_transmission name="r_ank_pitch"/>

  <link
    name="r_ank_roll">
    <inertial>
      <origin
        xyz="-0.0043379039627217 -0.0308901133838572 0.00235100351492532"
        rpy="0 0 0" />
      <mass
        value="0.0443088669743472" />
      
      <inertia ixx="0.00004034" ixy="0.00000019" ixz="0.00000012"
             iyy="0.00007874" iyz="-0.00000101"
             izz="0.00011579" />
    </inertial>
    <visual>
      <origin
        xyz="0 0 0"
        rpy="0 0 0" />
      <geometry>
        <mesh
          filename="package://rscuad_description/meshes/r_ank_roll.STL" />
      </geometry>
      <material
        name="">
        <color
          rgba="0.752941176470588 0.752941176470588 0.752941176470588 1" />
      </material>
    </visual>
    <collision>
      <origin
        xyz="0 0 0"
        rpy="0 0 0" />
      <geometry>
        <mesh
          filename="package://rscuad_description/meshes/r_ank_roll.STL" />
      </geometry>
    </collision>
  </link>
  <joint
    name="r_ank_roll"
    type="revolute">
    <origin
      xyz="0 0 0"
      rpy="0 0 3.1416" />
    <parent
      link="r_ank_pitch" />
    <child
      link="r_ank_roll" />
    <axis
      xyz="0 0 -1" />
     <limit effort="1000" velocity="10" lower="${-pi*0.9}" upper="${pi*0.9}" />
  </joint>
  <insert_transmission name="r_ank_roll"/>
</robot>